#VRML_SIM R2025a utf8

WorldInfo {
  coordinateSystem "EUN"
  basicTimeStep 32
  title "RiskAware SafeRL Construction Site Stage 4A"
}

Viewpoint {
  orientation -0.57735 0.57735 0.57735 2.0944
  position 4.5 4.5 4.5
}

DirectionalLight {
  ambientIntensity 0.55
  direction -0.4 -1 -0.3
  intensity 1
}

Solid {
  translation 0 -0.05 0
  name "construction floor"
  children [
    Shape {
      appearance PBRAppearance {
        baseColor 0.38 0.38 0.38
        roughness 0.9
        metalness 0
      }
      geometry Box {
        size 10 0.1 10
      }
    }
  ]
  boundingObject Box {
    size 10 0.1 10
  }
  locked TRUE
}

Solid {
  translation 1.6 0.25 0.5
  name "concrete barrier"
  children [
    Shape {
      appearance PBRAppearance {
        baseColor 0.55 0.55 0.55
        roughness 0.85
        metalness 0
      }
      geometry Box {
        size 1.8 0.5 0.45
      }
    }
  ]
  boundingObject Box {
    size 1.8 0.5 0.45
  }
  locked TRUE
}

Solid {
  translation -1.8 0.35 1.4
  name "material stack"
  children [
    Shape {
      appearance PBRAppearance {
        baseColor 0.52 0.26 0.08
        roughness 0.8
        metalness 0
      }
      geometry Box {
        size 1 0.7 1
      }
    }
  ]
  boundingObject Box {
    size 1 0.7 1
  }
  locked TRUE
}

Pose {
  translation -2.4 0.006 -1.8
  children [
    Shape {
      appearance PBRAppearance {
        baseColor 0.95 0.15 0.05
        transparency 0.45
        roughness 0.9
        metalness 0
      }
      geometry Box {
        size 2.2 0.012 1.8
      }
    }
  ]
}

Pose {
  translation 2.6 0.1 -2
  children [
    Shape {
      appearance PBRAppearance {
        baseColor 1 0.65 0
        roughness 0.7
        metalness 0
      }
      geometry Cylinder {
        height 0.2
        radius 0.35
      }
    }
  ]
}

DEF CONSTRUCTION_ROBOT Robot {
  translation 0 0.04 0
  rotation 0 1 0 0
  name "construction inspection robot"
  controller "live_bridge_robot"
  children [

    GPS {
      name "gps"
    }
    InertialUnit {
      name "inertial unit"
    }
    Compass {
      name "compass"
    }
    Emitter {
      name "bridge emitter"
      channel 7
    }
    Receiver {
      name "bridge receiver"
      channel 8
    }
    Pose {
      translation 0 0.04 0
      children [
        Shape {
          appearance PBRAppearance {
            baseColor 0.08 0.35 0.85
            roughness 0.5
            metalness 0.1
          }
          geometry Box {
            size 0.16 0.07 0.13
          }
        }
      ]
    }
    Pose {
      translation 0.055 0.085 0
      children [
        Shape {
          appearance PBRAppearance {
            baseColor 1 0.7 0.05
            emissiveColor 0.15 0.08 0
            roughness 0.4
            metalness 0
          }
          geometry Box {
            size 0.05 0.025 0.05
          }
        }
      ]
    }
    Pose {
      translation -0.07 -0.028 0
      children [
        Shape {
          appearance PBRAppearance {
            baseColor 0.12 0.12 0.12
            roughness 0.35
            metalness 0.2
          }
          geometry Sphere {
            radius 0.012
            subdivision 2
          }
        }
      ]
    }
    HingeJoint {
      jointParameters HingeJointParameters {
        axis 0 0 1
        anchor 0 0 0.075
      }
      device [
        RotationalMotor {
          name "left wheel motor"
          maxVelocity 12
          maxTorque 0.25
        }
        PositionSensor {
          name "left wheel sensor"
        }
      ]
      endPoint Solid {
        translation 0 0 0.075
        rotation 1 0 0 1.5708
        name "left wheel"
        children [
          Shape {
            appearance PBRAppearance {
              baseColor 0.03 0.03 0.03
              roughness 0.95
              metalness 0
            }
            geometry Cylinder {
              height 0.022
              radius 0.04
              subdivision 24
            }
          }
        ]
        boundingObject Cylinder {
          height 0.022
          radius 0.04
          subdivision 16
        }
        physics Physics {
          density -1
          mass 0.06
        }
      }
    }
    HingeJoint {
      jointParameters HingeJointParameters {
        axis 0 0 1
        anchor 0 0 -0.075
      }
      device [
        RotationalMotor {
          name "right wheel motor"
          maxVelocity 12
          maxTorque 0.25
        }
        PositionSensor {
          name "right wheel sensor"
        }
      ]
      endPoint Solid {
        translation 0 0 -0.075
        rotation 1 0 0 1.5708
        name "right wheel"
        children [
          Shape {
            appearance PBRAppearance {
              baseColor 0.03 0.03 0.03
              roughness 0.95
              metalness 0
            }
            geometry Cylinder {
              height 0.022
              radius 0.04
              subdivision 24
            }
          }
        ]
        boundingObject Cylinder {
          height 0.022
          radius 0.04
          subdivision 16
        }
        physics Physics {
          density -1
          mass 0.06
        }
      }
    }
    DistanceSensor {
      translation 0.085 0.055 0.045
      rotation 0 1 0 -0.55
      name "ps0"
      lookupTable [
        0 4095 0
        0.05 2500 0
        0.25 200 0
        0.5 0 0
      ]
    }
    DistanceSensor {
      translation 0.09 0.055 0.025
      rotation 0 1 0 -0.25
      name "ps1"
      lookupTable [
        0 4095 0
        0.05 2500 0
        0.25 200 0
        0.5 0 0
      ]
    }
    DistanceSensor {
      translation 0.09 0.055 -0.025
      rotation 0 1 0 0.25
      name "ps2"
      lookupTable [
        0 4095 0
        0.05 2500 0
        0.25 200 0
        0.5 0 0
      ]
    }
    DistanceSensor {
      translation 0.085 0.055 -0.045
      rotation 0 1 0 0.55
      name "ps3"
      lookupTable [
        0 4095 0
        0.05 2500 0
        0.25 200 0
        0.5 0 0
      ]
    }
    DistanceSensor {
      translation 0 0.055 0.072
      rotation 0 1 0 -1.5708
      name "ps4"
      lookupTable [
        0 4095 0
        0.05 2500 0
        0.25 200 0
        0.5 0 0
      ]
    }
    DistanceSensor {
      translation -0.075 0.055 0.04
      rotation 0 1 0 -2.6
      name "ps5"
      lookupTable [
        0 4095 0
        0.05 2500 0
        0.25 200 0
        0.5 0 0
      ]
    }
    DistanceSensor {
      translation -0.075 0.055 -0.04
      rotation 0 1 0 2.6
      name "ps6"
      lookupTable [
        0 4095 0
        0.05 2500 0
        0.25 200 0
        0.5 0 0
      ]
    }
    DistanceSensor {
      translation 0 0.055 -0.072
      rotation 0 1 0 1.5708
      name "ps7"
      lookupTable [
        0 4095 0
        0.05 2500 0
        0.25 200 0
        0.5 0 0
      ]
    }
  ]
  boundingObject Group {
    children [
      Pose {
        translation 0 0.04 0
        children [
          Box {
            size 0.16 0.07 0.13
          }
        ]
      }
      Pose {
        translation -0.07 -0.028 0
        children [
          Sphere {
            radius 0.012
            subdivision 2
          }
        ]
      }
    ]
  }
  physics Physics {
    density -1
    mass 0.8
  }
}

Robot {
  name "live bridge supervisor"
  supervisor TRUE
  controller "live_bridge_supervisor"
  children [
    Receiver {
      name "bridge receiver"
      channel 7
    }
    Emitter {
      name "bridge emitter"
      channel 8
    }
  ]
}
